import React from 'react';
import { render, screen } from '@testing-library/react';
import { ErrorBoundary, withErrorBoundary } from '../error-boundary';

// Test component that throws an error
const ThrowError = ({ shouldThrow = false }: { shouldThrow?: boolean }) => {
  if (shouldThrow) {
    throw new Error('Test error');
  }
  return <div>No error</div>;
};

// Mock console.error to prevent test output pollution
const originalError = console.error;
beforeAll(() => {
  console.error = jest.fn();
});

afterAll(() => {
  console.error = originalError;
});

describe('ErrorBoundary', () => {
  beforeEach(() => {
    jest.clearAllMocks();
  });

  it('should render children when there is no error', () => {
    render(
      <ErrorBoundary>
        <ThrowError shouldThrow={false} />
      </ErrorBoundary>
    );

    expect(screen.getByText('No error')).toBeInTheDocument();
  });

  it('should render error fallback when child component throws', () => {
    render(
      <ErrorBoundary>
        <ThrowError shouldThrow={true} />
      </ErrorBoundary>
    );

    expect(screen.getByText('Something went wrong')).toBeInTheDocument();
    expect(screen.getByText('Try again')).toBeInTheDocument();
  });

  it('should use custom fallback component when provided', () => {
    const CustomFallback = ({ error, resetError }: { error?: Error; resetError: () => void }) => (
      <div>
        <p>Custom error: {error?.message}</p>
        <button onClick={resetError}>Reset</button>
      </div>
    );

    render(
      <ErrorBoundary fallback={CustomFallback}>
        <ThrowError shouldThrow={true} />
      </ErrorBoundary>
    );

    expect(screen.getByText('Custom error: Test error')).toBeInTheDocument();
    expect(screen.getByText('Reset')).toBeInTheDocument();
  });

  it('should reset error state when resetError is called', () => {
    const { rerender } = render(
      <ErrorBoundary>
        <ThrowError shouldThrow={true} />
      </ErrorBoundary>
    );

    expect(screen.getByText('Something went wrong')).toBeInTheDocument();

    // Click the reset button
    screen.getByText('Try again').click();

    // Re-render with no error
    rerender(
      <ErrorBoundary>
        <ThrowError shouldThrow={false} />
      </ErrorBoundary>
    );

    expect(screen.getByText('No error')).toBeInTheDocument();
  });

  it('should log error information to console', () => {
    const consoleSpy = jest.spyOn(console, 'error').mockImplementation(() => {});

    render(
      <ErrorBoundary>
        <ThrowError shouldThrow={true} />
      </ErrorBoundary>
    );

    expect(consoleSpy).toHaveBeenCalled();
    consoleSpy.mockRestore();
  });
});

describe('withErrorBoundary HOC', () => {
  it('should wrap component with error boundary', () => {
    const TestComponent = () => <div>Test component</div>;
    const WrappedComponent = withErrorBoundary(TestComponent);

    render(<WrappedComponent />);

    expect(screen.getByText('Test component')).toBeInTheDocument();
  });

  it('should handle errors in wrapped component', () => {
    const WrappedThrowError = withErrorBoundary(ThrowError);

    render(<WrappedThrowError shouldThrow={true} />);

    expect(screen.getByText('Something went wrong')).toBeInTheDocument();
  });

  it('should pass props to wrapped component', () => {
    const TestComponent = ({ message }: { message: string }) => <div>{message}</div>;
    const WrappedComponent = withErrorBoundary(TestComponent);

    render(<WrappedComponent message="Hello World" />);

    expect(screen.getByText('Hello World')).toBeInTheDocument();
  });

  it('should use custom fallback with HOC', () => {
    const CustomFallback = () => <div>HOC Custom Error</div>;
    const TestComponent = () => <div>Test</div>;
    const WrappedComponent = withErrorBoundary(TestComponent, CustomFallback);

    render(<WrappedComponent />);

    expect(screen.getByText('Test')).toBeInTheDocument();
  });
});